2023-04-16 20:51:56,413 ERROR:Internal Server Error: /scrap/
Traceback (most recent call last):
  File "C:\Users\pyjte\AppData\Local\Packages\PythonSoftwareFoundation.Python.3.11_qbz5n2kfra8p0\LocalCache\local-packages\Python311\site-packages\django\core\handlers\exception.py", line 56, in inner
    response = get_response(request)
               ^^^^^^^^^^^^^^^^^^^^^
  File "C:\Users\pyjte\AppData\Local\Packages\PythonSoftwareFoundation.Python.3.11_qbz5n2kfra8p0\LocalCache\local-packages\Python311\site-packages\django\core\handlers\base.py", line 197, in _get_response
    response = wrapped_callback(request, *callback_args, **callback_kwargs)
               ^^^^^^^^^^^^^^^^^^^^^^^^^^^^^^^^^^^^^^^^^^^^^^^^^^^^^^^^^^^^
  File "C:\Users\pyjte\Desktop\Uni_Leeds\Year 3\Final Project\repo\final-project-site-map-generator-tool\sitemap_generator\sitemap_generator\views.py", line 49, in scrap
    ss1 = SiteScraper(url=root_url,
          ^^^^^^^^^^^^^^^^^^^^^^^^^
TypeError: __init__() should return None, not 'int'
2023-04-16 20:52:24,113 INFO:C:\Users\pyjte\Desktop\Uni_Leeds\Year 3\Final Project\repo\final-project-site-map-generator-tool\sitemap_generator\sitemap_generator\SiteScraper.py changed, reloading.
